INFO 2024-02-02 09:23:40,847 views Affichage de la liste des lettings.
WARNING 2024-02-02 09:23:40,916 log Not Found: /une_url_inexistante/
ERROR 2024-02-02 09:23:40,942 views Erreur interne du serveur déclenchée.
ERROR 2024-02-02 09:23:40,999 log Internal Server Error: /test-500/
Traceback (most recent call last):
  File "/home/walid/Bureau/oc_p13/venv/lib/python3.11/site-packages/django/core/handlers/exception.py", line 55, in inner
    response = get_response(request)
               ^^^^^^^^^^^^^^^^^^^^^
  File "/home/walid/Bureau/oc_p13/venv/lib/python3.11/site-packages/django/core/handlers/base.py", line 197, in _get_response
    response = wrapped_callback(request, *callback_args, **callback_kwargs)
               ^^^^^^^^^^^^^^^^^^^^^^^^^^^^^^^^^^^^^^^^^^^^^^^^^^^^^^^^^^^^
  File "/home/walid/Bureau/oc_p13/venv/lib/python3.11/site-packages/sentry_sdk/integrations/django/views.py", line 84, in sentry_wrapped_callback
    return callback(request, *args, **kwargs)
           ^^^^^^^^^^^^^^^^^^^^^^^^^^^^^^^^^^
  File "/home/walid/Bureau/oc_p13/oc_lettings_site/views.py", line 57, in test_500
    raise ValueError("Test d'erreur 500")
ValueError: Test d'erreur 500
INFO 2024-02-02 09:23:41,025 views Affichage de la page d'accueil.
INFO 2024-02-02 09:23:41,053 views Affichage de la page d'accueil.
WARNING 2024-02-02 09:23:41,080 log Not Found: /chemin_inexistant/
ERROR 2024-02-02 09:23:41,108 views Erreur interne du serveur déclenchée.
ERROR 2024-02-02 09:23:41,132 log Internal Server Error: /test-500/
Traceback (most recent call last):
  File "/home/walid/Bureau/oc_p13/venv/lib/python3.11/site-packages/django/core/handlers/exception.py", line 55, in inner
    response = get_response(request)
               ^^^^^^^^^^^^^^^^^^^^^
  File "/home/walid/Bureau/oc_p13/venv/lib/python3.11/site-packages/django/core/handlers/base.py", line 197, in _get_response
    response = wrapped_callback(request, *callback_args, **callback_kwargs)
               ^^^^^^^^^^^^^^^^^^^^^^^^^^^^^^^^^^^^^^^^^^^^^^^^^^^^^^^^^^^^
  File "/home/walid/Bureau/oc_p13/venv/lib/python3.11/site-packages/sentry_sdk/integrations/django/views.py", line 84, in sentry_wrapped_callback
    return callback(request, *args, **kwargs)
           ^^^^^^^^^^^^^^^^^^^^^^^^^^^^^^^^^^
  File "/home/walid/Bureau/oc_p13/oc_lettings_site/views.py", line 57, in test_500
    raise ValueError("Test d'erreur 500")
ValueError: Test d'erreur 500
INFO 2024-02-02 09:23:41,538 views Quelque chose s'est produit avec l'utilisateur : testuser
INFO 2024-02-02 09:23:42,287 views Quelque chose s'est produit avec l'utilisateur : testuser
INFO 2024-02-02 09:23:45,189 views Affichage de la liste des profils.
INFO 2024-02-02 09:23:45,224 views Affichage de la liste des profils.
INFO 2024-02-02 09:23:45,254 views Affichage de la liste des profils.
INFO 2024-02-02 09:23:45,677 views Quelque chose s'est produit avec l'utilisateur : testuser
INFO 2024-02-02 09:23:45,702 views Quelque chose s'est produit avec l'utilisateur : testuser
INFO 2024-02-02 09:23:45,728 views Quelque chose s'est produit avec l'utilisateur : testuser
